Workbook

Sheet 推理总览
A1: GraphCast 推理算子对照
A2: 单位：40步设备累计ms，非E2E、非单次时延。平台实际shape和次数可不同；点击单元格查看完整记录。
A3: †＝该格仅独立/已确认部分，其他耗时另列；不能与Native全量直接求加速比。‘—’不是0；‘未确认’不代表不支持。
A4: 910C仅mul为10/21，其余10/20，不合计为新版整模耗时。S5000/BW1101本批Native整模诊断未通过。H100、旧BW1000历史推理在证据页。
D5: C550 | F5: S5000 | H5: 910C | J5: BW1101 | L5: 810E
A6: 逻辑类型数：Native / 完整接管 | D6: 14 | E6: 12 | F6: 14 | G6: 13 | H6: 12 | I6: 10 | J6: 14 | K6: 12 | L6: 14 | M6: 13
A7: 覆盖率（目标≥80%） | D7: =E6/D6 -> 0.85714286 | F7: =G6/F6 -> 0.92857143 | H7: =I6/H6 -> 0.83333333 | J7: =K6/J6 -> 0.85714286 | L7: =M6/L6 -> 0.92857143
A9: 类型 | B9: 算子/执行名称 | C9: 对应运算 / 范围 | D9: C550 | F9: S5000 | H9: 910C | J9: BW1101 | L9: 810E
D10: Native (ms) | E10: FlagGems (ms) | F10: Native (ms) | G10: FlagGems (ms) | H10: Native (ms) | I10: FlagGems (ms) | J10: Native (ms) | K10: FlagGems (ms) | L10: Native (ms) | M10: FlagGems (ms)
A11: 独立算子｜Native为逻辑全量；FlagGems只计本行独立执行，拆分项标†
A12: 独立 | B12: addmm | C12: torch.addmm | D12: ='证据与历史'!G55 -> 12260.309 | E12: ='证据与历史'!H55 -> 22223.036 | F12: ='证据与历史'!G36 -> 6063.2013 | G12: ='证据与历史'!H36 -> 8475.0823 | H12: ='证据与历史'!G3 -> 7750.804 | I12: 见融合/混合组 | J12: ='证据与历史'!G71 -> 29766.827 | K12: 见融合/混合组 | L12: ='证据与历史'!G18 -> 13818.696 | M12: ='证据与历史'!H18 -> 46547.617
A13: 独立 | B13: cat | C13: torch.cat | D13: ='证据与历史'!G56 -> 1337.5532 | E13: ='证据与历史'!H56 -> 1012.8197 | F13: ='证据与历史'!G37 -> 511.91909 | G13: ='证据与历史'!H37 -> 4642.5603 | H13: ='证据与历史'!G4 -> 525.5732 | I13: 未确认 | J13: ='证据与历史'!G72 -> 703.48883 | K13: ='证据与历史'!H72 -> 477.38354 | L13: ='证据与历史'!G19 -> 361.35177 | M13: ='证据与历史'!H19 -> 398.20417
A14: 独立 | B14: native_layer_norm | C14: F.layer_norm | D14: ='证据与历史'!G57 -> 2719.6703 | E14: ='证据与历史'!H57 -> 3412.1777 | F14: ='证据与历史'!G38 -> 2557.9691 | G14: ='证据与历史'!H38 -> 2054.5788 | H14: ='证据与历史'!G5 -> 3751.973 | I14: ='证据与历史'!H5 -> 4003.7489 | J14: ='证据与历史'!G73 -> 8271.5864 | K14: ='证据与历史'!H73 -> 3864.7694 | L14: ='证据与历史'!G20 -> 2180.4498 | M14: ='证据与历史'!H20 -> 1492.2736
A15: 独立 | B15: index_add_ | C15: Tensor.index_add_ | D15: ='证据与历史'!G58 -> 2130.8961 | E15: ='证据与历史'!H58 -> 1653.4385 | F15: ='证据与历史'!G39 -> 1880.8756 | G15: ='证据与历史'!H39 -> 1650.2695 | H15: ='证据与历史'!G6 -> 6171.5522 | I15: ='证据与历史'!H6 -> 2018.745 | J15: ='证据与历史'!G74 -> 2790.9982 | K15: ='证据与历史'!H74 -> 2016.9974 | L15: ='证据与历史'!G21 -> 2392.6995 | M15: ='证据与历史'!H21 -> 2222.5714
A16: 独立 | B16: silu | C16: F.silu | D16: ='证据与历史'!G59 -> 2187.3582 | E16: ='证据与历史'!H59 -> 2210.2292 | F16: ='证据与历史'!G40 -> 2468.7596 | G16: ='证据与历史'!H40 -> 125.92526 | H16: ='证据与历史'!G7 -> 2521.8362 | I16: ='证据与历史'!H7 -> 149.42661 | J16: ='证据与历史'!G75 -> 2709.3887 | K16: ='证据与历史'!H75 -> 93.31672 | L16: ='证据与历史'!G22 -> 1607.476 | M16: ='证据与历史'!H22 -> 1584.42
A17: 独立 | B17: index | C17: Tensor.__getitem__ | D17: ='证据与历史'!G60 -> 1931.3295 | E17: ='证据与历史'!H60 -> 1857.4198 | F17: ='证据与历史'!G41 -> 1883.7574 | G17: ='证据与历史'!H41 -> 1853.6488 | H17: ='证据与历史'!G8 -> 5769.764 | I17: ='证据与历史'!H8 -> 4817.0948 | J17: ='证据与历史'!G76 -> 5060.3835 | K17: ='证据与历史'!H76 -> 7.181837 | L17: ='证据与历史'!G23 -> 1156.2951 | M17: ='证据与历史'!H23 -> 992.92191
A18: 独立 | B18: add | C18: torch.add | D18: ='证据与历史'!G61 -> 4698.5477 | E18: ='证据与历史'!H61 -> 4728.4142 | F18: ='证据与历史'!G42 -> 4963.3587 | G18: ='证据与历史'!H42 -> 993.49001 | H18: ='证据与历史'!G9 -> 6197.3184 | I18: ='证据与历史'!H9 -> 2338.5797 | J18: ='证据与历史'!G77 -> 3891.7985 | K18: ='证据与历史'!H77 -> 820.21896 | L18: ='证据与历史'!G24 -> 3357.636 | M18: ='证据与历史'!H24 -> 3350.9121
A19: 独立 | B19: _copy_from | C19: aten::_copy_from | D19: — | E19: — | F19: ='证据与历史'!G43 -> 266.00282 | G19: 未确认 | H19: — | I19: — | J19: — | K19: — | L19: — | M19: —
A20: 独立 | B20: abs | C20: torch.abs | D20: ='证据与历史'!G62 -> 0.567808 | E20: ='证据与历史'!H62 -> 0.56064 | F20: ='证据与历史'!G44 -> 0.537362 | G20: ='证据与历史'!H44 -> 0.516762 | H20: — | I20: — | J20: ='证据与历史'!G78 -> 0.387678 | K20: ='证据与历史'!H78 -> 0.390398 | L20: ='证据与历史'!G25 -> 0.344723 | M20: ='证据与历史'!H25 -> 0.346883
A21: 独立 | B21: all | C21: torch.all | D21: ='证据与历史'!G63 -> 0.074496 | E21: ='证据与历史'!H63 -> 0.083712 | F21: ='证据与历史'!G45 -> 0.246922 | G21: ='证据与历史'!H45 -> 0.15816 | H21: ='证据与历史'!G10 -> 0.089562 | I21: ='证据与历史'!H10 -> 0.327787 | J21: ='证据与历史'!G79 -> 0.127999 | K21: ='证据与历史'!H79 -> 0.099837 | L21: ='证据与历史'!G26 -> 0.093401 | M21: ='证据与历史'!H26 -> 7.618454
A22: 独立 | B22: copy_ | C22: Tensor.copy_ | D22: ='证据与历史'!G64 -> 3501.7605 | E22: ='证据与历史'!H64 -> 1853.2145 | F22: — | G22: ='证据与历史'!H50 -> 123.9513 | H22: ='证据与历史'!G11 -> 1842.2872 | I22: 未确认 | J22: ='证据与历史'!G80 -> 243.42566 | K22: 未确认 | L22: ='证据与历史'!G27 -> 221.63738 | M22: ='证据与历史'!H27 -> 121.93949
A23: 独立 | B23: eq | C23: torch.eq | D23: ='证据与历史'!G65 -> 0.292352 | E23: ='证据与历史'!H65 -> 0.291584 | F23: ='证据与历史'!G46 -> 0.292642 | G23: ='证据与历史'!H46 -> 0.28996 | H23: — | I23: — | J23: ='证据与历史'!G81 -> 0.251039 | K23: ='证据与历史'!H81 -> 0.294238 | L23: ='证据与历史'!G28 -> 0.202642 | M23: ='证据与历史'!H28 -> 0.195922
A24: 独立 | B24: fill_ | C24: Tensor.fill_ | D24: ='证据与历史'!G66 -> 95.644672 | E24: 未确认 | F24: — | G24: — | H24: — | I24: — | J24: ='证据与历史'!G82 -> 134.80258 | K24: 未确认 | L24: ='证据与历史'!G29 -> 66.321168 | M24: ='证据与历史'!H29 -> 2.673025
A25: 独立 | B25: isfinite | C25: torch.isfinite | D25: — | E25: — | F25: — | G25: — | H25: ='证据与历史'!G12 -> 0.427328 | I25: ='证据与历史'!H12 -> 2.048581 | J25: — | K25: — | L25: — | M25: —
A26: 独立 | B26: mul | C26: torch.mul | D26: ='证据与历史'!G67 -> 121.40851 | E26: ='证据与历史'!H67 -> 377.0715 | F26: ='证据与历史'!G47 -> 110.48268 | G26: ='证据与历史'!H47 -> 87.417388 | H26: ='证据与历史'!G13 -> 203.6492 | I26: ='证据与历史'!H13 -> 454.43316 | J26: ='证据与历史'!G83 -> 57.521795 | K26: ='证据与历史'!H83 -> 48.681318 | L26: ='证据与历史'!G30 -> 50.95436 | M26: ='证据与历史'!H30 -> 69.706643
A27: 独立 | B27: ne | C27: torch.ne | D27: ='证据与历史'!G68 -> 0.288256 | E27: ='证据与历史'!H68 -> 0.287744 | F27: ='证据与历史'!G48 -> 0.31064 | G27: ='证据与历史'!H48 -> 0.31444 | H27: — | I27: — | J27: ='证据与历史'!G84 -> 0.237919 | K27: ='证据与历史'!H84 -> 0.283198 | L27: ='证据与历史'!G31 -> 0.213921 | M27: ='证据与历史'!H31 -> 0.208361
A28: 独立 | B28: zero_ | C28: Tensor.zero_ | D28: — | E28: ='证据与历史'!H69 -> 99.881216 | F28: ='证据与历史'!G49 -> 89.41099 | G28: ='证据与历史'!H49 -> 104.36434 | H28: ='证据与历史'!G14 -> 80.620027 | I28: ='证据与历史'!H14 -> 153.7169 | J28: — | K28: ='证据与历史'!H90 -> 145.6764 | L28: — | M28: ='证据与历史'!H32 -> 64.77564
A29: 融合算子｜每个实际融合kernel只计一次，不分摊到上方算子
A30: 融合 | B30: silu_to_tf32_fp16 | C30: silu + TF32舍入/FP16打包 | D30: — | E30: — | F30: — | G30: ='证据与历史'!H51 -> 849.12872 | H30: — | I30: — | J30: — | K30: — | L30: — | M30: —
A31: 融合 | B31: add_add_silu_to_tf32_fp16 | C31: add × 2 → silu + TF32舍入/FP16打包 | D31: — | E31: — | F31: — | G31: ='证据与历史'!H52 -> 1990.9198 | H31: — | I31: — | J31: — | K31: — | L31: — | M31: —
A32: 融合 | B32: post_layer_norm_residual | C32: native_layer_norm → add（残差） | D32: — | E32: — | F32: — | G32: ='证据与历史'!H53 -> 493.93785 | H32: — | I32: — | J32: — | K32: ='证据与历史'!H87 -> 692.74297 | L32: — | M32: —
A33: 融合 | B33: add_add_silu | C33: add × 2 → silu | D33: — | E33: — | F33: — | G33: — | H33: — | I33: ='证据与历史'!H15 -> 2807.7276 | J33: — | K33: ='证据与历史'!H85 -> 8.44172 | L33: — | M33: —
A34: 融合 | B34: gather_gather_add_silu | C34: index × 2 + add × 2 → silu | D34: — | E34: — | F34: — | G34: — | H34: — | I34: — | J34: — | K34: ='证据与历史'!H86 -> 1753.7903 | L34: — | M34: —
A35: 未拆分内核组｜包含普通与融合调用，不能当作纯融合计时
A36: 混合组 | B36: addmm / addmm_silu（未拆分） | C36: addmm；部分调用融合 silu | D36: — | E36: — | F36: — | G36: — | H36: — | I36: ='证据与历史'!H16 -> 13758.866 | J36: — | K36: ='证据与历史'!H88 -> 13409.365 | L36: — | M36: —
A37: 准备与辅助执行｜属于已确认FlagGems执行，但不新增覆盖率类型
A38: 辅助 | B38: round_to_tf32_copy | C38: addmm 内部舍入/打包 | D38: — | E38: — | F38: — | G38: ='证据与历史'!H54 -> 4295.0317 | H38: — | I38: — | J38: — | K38: — | L38: — | M38: —
A39: 检查辅助执行｜不新增覆盖率类型
A40: 辅助 | B40: index_bounds | C40: 索引检查辅助 | D40: — | E40: — | F40: — | G40: — | H40: — | I40: — | J40: — | K40: ='证据与历史'!H89 -> 10.609026 | L40: — | M40: —
A41: 未确认归属的11条执行记录保留在证据页，不填入FlagGems计时列。

Sheet 推理覆盖率
A1: 推理覆盖率
A2: 按Native逻辑类型计覆盖率；融合不增加分母。独立、融合及辅助执行耗时统一见“推理总览”，点击下方链接查看。
A3: 平台 | B3: Native类型数 | C3: 完整接管数 | D3: 完整覆盖率 | E3: 核心命中
A4: C550 | B4: 14 | C4: 12 | D4: =C4/B4 -> 0.85714286 | E4: 7/7
A5: S5000 | B5: 14 | C5: 13 | D5: =C5/B5 -> 0.92857143 | E5: 7/7
A6: 910C | B6: 12 | C6: 10 | D6: =C6/B6 -> 0.83333333 | E6: 6/7
A7: 海光 BW1101 | B7: 14 | C7: 12 | D7: =C7/B7 -> 0.85714286 | E7: 7/7
A8: 810E | B8: 14 | C8: 13 | D8: =C8/B8 -> 0.92857143 | E8: 7/7
A9: 完整/部分/未计入是接管结论；独立/融合是实现方式，两者分开。下方68条是平台×逻辑算子记录，不是68种不同算子。
A10: 平台 | B10: Native逻辑算子 | C10: 接管状态 | D10: 实现方式 | E10: 独立/辅助执行项 | F10: 融合/含融合执行项 | G10: 计入分子 | H10: 说明 | I10: 执行项编号 | J10: 算子耗时
A11: C550 | B11: addmm | C11: 完整 | D11: 独立 | E11: addmm | F11: — | G11: 是 | H11: 完整接管范围限本轮实际调用。 | I11: C550-E01 | J11: 查看耗时
A12: C550 | B12: cat | C12: 完整 | D12: 独立 | E12: cat | F12: — | G12: 是 | H12: 完整接管范围限本轮实际调用。 | I12: C550-E02 | J12: 查看耗时
A13: C550 | B13: native_layer_norm | C13: 完整 | D13: 独立 | E13: native_layer_norm | F13: — | G13: 是 | H13: 完整接管范围限本轮实际调用。 | I13: C550-E03 | J13: 查看耗时
A14: C550 | B14: index_add_ | C14: 完整 | D14: 独立 | E14: index_add_ | F14: — | G14: 是 | H14: 完整接管范围限本轮实际调用。 | I14: C550-E04 | J14: 查看耗时
A15: C550 | B15: silu | C15: 完整 | D15: 独立 | E15: silu | F15: — | G15: 是 | H15: 完整接管范围限本轮实际调用。 | I15: C550-E05 | J15: 查看耗时
A16: C550 | B16: index | C16: 完整 | D16: 独立 | E16: index | F16: — | G16: 是 | H16: 完整接管范围限本轮实际调用。 | I16: C550-E06 | J16: 查看耗时
A17: C550 | B17: add | C17: 完整 | D17: 独立 | E17: add | F17: — | G17: 是 | H17: 完整接管范围限本轮实际调用。 | I17: C550-E07 | J17: 查看耗时
A18: C550 | B18: abs | C18: 完整 | D18: 独立 | E18: abs | F18: — | G18: 是 | H18: 完整接管范围限本轮实际调用。 | I18: C550-E08 | J18: 查看耗时
A19: C550 | B19: all | C19: 完整 | D19: 独立 | E19: all | F19: — | G19: 是 | H19: 完整接管范围限本轮实际调用。 | I19: C550-E09 | J19: 查看耗时
A20: C550 | B20: copy_ | C20: 部分 | D20: 独立＋未归属残留 | E20: copy_ | F20: — | G20: 否 | H20: 仅部分调用有FG证据，不计完整接管。 | I20: C550-E10 C550-E16 | J20: 查看耗时
A21: C550 | B21: eq | C21: 完整 | D21: 独立 | E21: eq | F21: — | G21: 是 | H21: 完整接管范围限本轮实际调用。 | I21: C550-E11 | J21: 查看耗时
... A78: 810E | B78: ne | C78: 完整 | D78: 独立 | E78: ne | F78: — | G78: 是 | H78: 完整接管范围限本轮实际调用。 | I78: 810E-E14 | J78: 查看耗时

Sheet 训练总览
A1: GraphCast 训练算子对照｜v5.4.0附件记录
A2: 单位：累计ms。B1R1实际相位次数×逐case三轮计时中位数，含记录的重算；不是整模训练E2E。原数值保留。
A3: 点击时间或状态查看case验证、次数、shape和备注。‘无完整计时’不代表不支持；不补算未通过或缺失case。
A4: 训练仍使用附件的BW1000标签，不与推理BW1101合并；各平台实际case集合可能不同，不能直接按总耗时作硬件排名。
A6: 阶段 | B6: 算子 | C6: 顶层API | D6: H100 | F6: C550 | H6: S5000 | J6: 910C | L6: BW1000（历史机型） | N6: 810E
D7: Native (ms) | E7: FlagGems (ms) | F7: Native (ms) | G7: FlagGems (ms) | H7: Native (ms) | I7: FlagGems (ms) | J7: Native (ms) | K7: FlagGems (ms) | L7: Native (ms) | M7: FlagGems (ms) | N7: Native (ms) | O7: FlagGems (ms)
A8: 训练前向
A9: 前向 | B9: addmm | C9: torch.addmm | D9: ='证据与历史'!G91 -> 577.76785 | E9: ='证据与历史'!H91 -> 1376.8837 | F9: ='证据与历史'!G135 -> 866.20335 | G9: ='证据与历史'!H135 -> 1330.0167 | H9: ='证据与历史'!G179 -> 1143.4689 | I9: ='证据与历史'!H179 -> 3747.275 | J9: ='证据与历史'!G223 -> 402.31135 | K9: ='证据与历史'!H223 -> 646.1211 | L9: ='证据与历史'!G267 -> 782.9559 | M9: ='证据与历史'!H267 -> 1101.4855 | N9: ='证据与历史'!G311 -> 869.10088 | O9: ='证据与历史'!H311 -> 2788.0283
A10: 前向 | B10: cat | C10: torch.cat | D10: ='证据与历史'!G92 -> 55.815254 | E10: ='证据与历史'!H92 -> 56.444109 | F10: ='证据与历史'!G136 -> 150.46993 | G10: ='证据与历史'!H136 -> 123.25747 | H10: ='证据与历史'!G180 -> 121.6182 | I10: ='证据与历史'!H180 -> 413.3947 | J10: ='证据与历史'!G224 -> 131.40459 | K10: ='证据与历史'!H224 -> 53146.206 | L10: 无完整计时 | M10: 无完整计时 | N10: ='证据与历史'!G312 -> 75.025444 | O10: ='证据与历史'!H312 -> 76.751078
A11: 前向 | B11: native_layer_norm | C11: torch.nn.functional.layer_norm | D11: 无完整计时 | E11: 无完整计时 | F11: ='证据与历史'!G137 -> 73.127757 | G11: ='证据与历史'!H137 -> 141.49929 | H11: ='证据与历史'!G181 -> 64.499505 | I11: ='证据与历史'!H181 -> 81.147539 | J11: ='证据与历史'!G225 -> 97.950925 | K11: ='证据与历史'!H225 -> 125.6963 | L11: ='证据与历史'!G269 -> 126.01247 | M11: ='证据与历史'!H269 -> 113.17891 | N11: 无完整计时 | O11: 无完整计时
A12: 前向 | B12: index_add_ | C12: Tensor.index_add_ | D12: ='证据与历史'!G94 -> 37.14416 | E12: ='证据与历史'!H94 -> 37.995495 | F12: ='证据与历史'!G138 -> 55.065301 | G12: ='证据与历史'!H138 -> 188.77292 | H12: ='证据与历史'!G182 -> 46.916394 | I12: ='证据与历史'!H182 -> 2083.8972 | J12: 无完整计时 | K12: 无完整计时 | L12: ='证据与历史'!G270 -> 60.504294 | M12: ='证据与历史'!H270 -> 62.362838 | N12: ='证据与历史'!G314 -> 59.876296 | O12: ='证据与历史'!H314 -> 63.903708
A13: 前向 | B13: silu | C13: torch.nn.functional.silu | D13: 无完整计时 | E13: 无完整计时 | F13: ='证据与历史'!G139 -> 61.714799 | G13: ='证据与历史'!H139 -> 142.3349 | H13: ='证据与历史'!G183 -> 60.067092 | I13: ='证据与历史'!H183 -> 94.240533 | J13: ='证据与历史'!G227 -> 64.412332 | K13: ='证据与历史'!H227 -> 116.2753 | L13: ='证据与历史'!G271 -> 66.997371 | M13: ='证据与历史'!H271 -> 117.32976 | N13: 无完整计时 | O13: 无完整计时
A14: 前向 | B14: index | C14: Tensor.__getitem__ | D14: ='证据与历史'!G96 -> 19.962441 | E14: ='证据与历史'!H96 -> 21.776909 | F14: ='证据与历史'!G140 -> 48.320273 | G14: ='证据与历史'!H140 -> 59.596408 | H14: 无完整计时 | I14: 无完整计时 | J14: ='证据与历史'!G228 -> 140.81715 | K14: ='证据与历史'!H228 -> 131.88602 | L14: ='证据与历史'!G272 -> 66.921783 | M14: ='证据与历史'!H272 -> 64.37138 | N14: ='证据与历史'!G316 -> 29.105617 | O14: ='证据与历史'!H316 -> 28.19686
A15: 前向 | B15: add | C15: torch.add | D15: ='证据与历史'!G97 -> 17.876172 | E15: ='证据与历史'!H97 -> 22.849648 | F15: 无完整计时 | G15: 无完整计时 | H15: ='证据与历史'!G185 -> 38.472315 | I15: ='证据与历史'!H185 -> 43.32036 | J15: ='证据与历史'!G229 -> 43.320599 | K15: ='证据与历史'!H229 -> 80.965801 | L15: 无完整计时 | M15: 无完整计时 | N15: ='证据与历史'!G317 -> 24.786452 | O15: ='证据与历史'!H317 -> 29.522985
A16: 前向 | B16: copy_ | C16: torch.ops.aten.copy_ | D16: ='证据与历史'!G98 -> 58.682521 | E16: 无完整计时 | F16: ='证据与历史'!G142 -> 171.00138 | G16: 无完整计时 | H16: ='证据与历史'!G186 -> 50.477623 | I16: 无完整计时 | J16: ='证据与历史'!G230 -> 67.022755 | K16: 无完整计时 | L16: 无完整计时 | M16: 无完整计时 | N16: ='证据与历史'!G318 -> 52.365888 | O16: 无完整计时
A17: 前向 | B17: fill_ | C17: torch.ops.aten.fill_ | D17: ='证据与历史'!G99 -> 1.4137312 | E17: ='证据与历史'!H99 -> 1.7354592 | F17: ='证据与历史'!G143 -> 3.1610453 | G17: ='证据与历史'!H143 -> 8.5768619 | H17: ='证据与历史'!G187 -> 2.8439253 | I17: ='证据与历史'!H187 -> 3.4131253 | J17: ='证据与历史'!G231 -> 2.6197533 | K17: ='证据与历史'!H231 -> 4.4077327 | L17: ='证据与历史'!G275 -> 3.7035227 | M17: ='证据与历史'!H275 -> 7.0874132 | N17: ='证据与历史'!G319 -> 1.924264 | O17: ='证据与历史'!H319 -> 2.7332787
A18: 前向 | B18: mul | C18: torch.mul | D18: 无完整计时 | E18: 无完整计时 | F18: 无完整计时 | G18: 无完整计时 | H18: 无完整计时 | I18: 无完整计时 | J18: 无完整计时 | K18: 无完整计时 | L18: 无完整计时 | M18: 无完整计时 | N18: 无完整计时 | O18: 无完整计时
A19: 前向 | B19: sub | C19: torch.ops.aten.sub | D19: 无完整计时 | E19: 无完整计时 | F19: ='证据与历史'!G145 -> 4.2003883 | G19: ='证据与历史'!H145 -> 5.6734208 | H19: ='证据与历史'!G189 -> 5.0132773 | I19: ='证据与历史'!H189 -> 4.1189307 | J19: ='证据与历史'!G233 -> 10.922775 | K19: ='证据与历史'!H233 -> 18.70498 | L19: 无完整计时 | M19: 无完整计时 | N19: 无完整计时 | O19: 无完整计时
A20: 前向 | B20: sum | C20: torch.sum | D20: 无完整计时 | E20: 无完整计时 | F20: ='证据与历史'!G146 -> 0.87886506 | G20: ='证据与历史'!H146 -> 36.985455 | H20: ='证据与历史'!G190 -> 0.534364 | I20: ='证据与历史'!H190 -> 49.409111 | J20: ='证据与历史'!G234 -> 1.8417087 | K20: ='证据与历史'!H234 -> 11.000037 | L20: 无完整计时 | M20: 无完整计时 | N20: 无完整计时 | O20: 无完整计时
A21: 前向 | B21: pow | C21: torch.ops.aten.pow | D21: 无完整计时 | E21: 无完整计时 | F21: ='证据与历史'!G147 -> 0.68570454 | G21: ='证据与历史'!H147 -> 7.1890005 | H21: ='证据与历史'!G191 -> 0.4313 | I21: ='证据与历史'!H191 -> 4.6095066 | J21: ='证据与历史'!G235 -> 0.899256 | K21: ='证据与历史'!H235 -> 5.113666 | L21: ='证据与历史'!G279 -> 0.86068213 | M21: ='证据与历史'!H279 -> 5.8151964 | N21: 无完整计时 | O21: 无完整计时
A22: 前向 | B22: mean | C22: torch.ops.aten.mean | D22: ='证据与历史'!G104 -> 0.015088 | E22: ='证据与历史'!H104 -> 0.074001066 | F22: ='证据与历史'!G148 -> 0.025770667 | G22: ='证据与历史'!H148 -> 0.3093504 | H22: ='证据与历史'!G192 -> 0.020414667 | I22: ='证据与历史'!H192 -> 0.11077867 | J22: ='证据与历史'!G236 -> 0.050528667 | K22: ='证据与历史'!H236 -> 0.23940533 | L22: ='证据与历史'!G280 -> 0.051168 | M22: ='证据与历史'!H280 -> 0.26121586 | N22: ='证据与历史'!G324 -> 0.016432 | O22: ='证据与历史'!H324 -> 0.084054667
A23: 前向 | B23: div | C23: torch.ops.aten.div | D23: 无完整计时 | E23: 无完整计时 | F23: 无完整计时 | G23: 无完整计时 | H23: 无完整计时 | I23: 无完整计时 | J23: 无完整计时 | K23: 无完整计时 | L23: 无完整计时 | M23: 无完整计时 | N23: 无完整计时 | O23: 无完整计时
A24: 前向 | B24: abs | C24: torch.ops.aten.abs | D24: 本次未出现 | E24: 本次未出现 | F24: 本次未出现 | G24: 本次未出现 | H24: 本次未出现 | I24: 本次未出现 | J24: 本次未出现 | K24: 本次未出现 | L24: 本次未出现 | M24: 本次未出现 | N24: 本次未出现 | O24: 本次未出现
A25: 前向 | B25: ne | C25: torch.ops.aten.ne | D25: 本次未出现 | E25: 本次未出现 | F25: 本次未出现 | G25: 本次未出现 | H25: 本次未出现 | I25: 本次未出现 | J25: 本次未出现 | K25: 本次未出现 | L25: 本次未出现 | M25: 本次未出现 | N25: 本次未出现 | O25: 本次未出现
A26: 前向 | B26: eq | C26: torch.ops.aten.eq | D26: 本次未出现 | E26: 本次未出现 | F26: 本次未出现 | G26: 本次未出现 | H26: 本次未出现 | I26: 本次未出现 | J26: 本次未出现 | K26: 本次未出现 | L26: 本次未出现 | M26: 本次未出现 | N26: 本次未出现 | O26: 本次未出现
A27: 前向 | B27: all | C27: torch.ops.aten.all | D27: 本次未出现 | E27: 本次未出现 | F27: 本次未出现 | G27: 本次未出现 | H27: 本次未出现 | I27: 本次未出现 | J27: 本次未出现 | K27: 本次未出现 | L27: 本次未出现 | M27: 本次未出现 | N27: 本次未出现 | O27: 本次未出现
A28: 前向 | B28: _local_scalar_dense | C28: torch.ops.aten._local_scalar_dense | D28: 本次未出现 | E28: 本次未出现 | F28: 本次未出现 | G28: 本次未出现 | H28: 本次未出现 | I28: 本次未出现 | J28: 本次未出现 | K28: 本次未出现 | L28: 本次未出现 | M28: 本次未出现 | N28: 本次未出现 | O28: 本次未出现
A29: 前向 | B29: clamp_min | C29: torch.ops.aten.clamp_min | D29: ='证据与历史'!G111 -> 0.013264 | E29: ='证据与历史'!H111 -> 0.097054934 | F29: ='证据与历史'!G155 -> 0.019968 | G29: ='证据与历史'!H155 -> 0.381312 | H29: ='证据与历史'!G199 -> 0.019404 | I29: ='证据与历史'!H199 -> 0.149076 | J29: ='证据与历史'!G243 -> 0.049208 | K29: ='证据与历史'!H243 -> 0.26388733 | L29: ='证据与历史'!G287 -> 0.046645333 | M29: ='证据与历史'!H287 -> 0.29052797 | N29: ='证据与历史'!G331 -> 0.014681333 | O29: ='证据与历史'!H331 -> 0.117332
A30: 前向 | B30: index_select | C30: torch.ops.aten.index_select | D30: 本次未出现 | E30: 本次未出现 | F30: 本次未出现 | G30: 本次未出现 | H30: 本次未出现 | I30: 本次未出现 | J30: 本次未出现 | K30: 本次未出现 | L30: 本次未出现 | M30: 本次未出现 | N30: 本次未出现 | O30: 本次未出现
A31: 训练反向
A32: 反向 | B32: addmm | C32: torch.addmm | D32: ='证据与历史'!G113 -> 1265.7895 | E32: ='证据与历史'!H113 -> 3019.998 | F32: ='证据与历史'!G157 -> 1873.6133 | G32: ='证据与历史'!H157 -> 2932.7486 | H32: ='证据与历史'!G201 -> 2502.1966 | I32: ='证据与历史'!H201 -> 8140.758 | J32: ='证据与历史'!G245 -> 883.50398 | K32: ='证据与历史'!H245 -> 1434.8956 | L32: ='证据与历史'!G289 -> 1720.0247 | M32: ='证据与历史'!H289 -> 2417.4792 | N32: ='证据与历史'!G333 -> 1901.0214 | O32: ='证据与历史'!H333 -> 6118.8318
A33: 反向 | B33: cat | C33: torch.cat | D33: ='证据与历史'!G114 -> 135.84368 | E33: ='证据与历史'!H114 -> 150.29778 | F33: ='证据与历史'!G158 -> 390.52087 | G33: ='证据与历史'!H158 -> 302.82755 | H33: ='证据与历史'!G202 -> 323.43719 | I33: ='证据与历史'!H202 -> 843.25775 | J33: ='证据与历史'!G246 -> 360.21633 | K33: ='证据与历史'!H246 -> 127528.58 | L33: 无完整计时 | M33: 无完整计时 | N33: ='证据与历史'!G334 -> 184.3527 | O33: ='证据与历史'!H334 -> 209.75901
A34: 反向 | B34: native_layer_norm | C34: torch.nn.functional.layer_norm | D34: 无完整计时 | E34: 无完整计时 | F34: ='证据与历史'!G159 -> 147.46237 | G34: ='证据与历史'!H159 -> 261.83502 | H34: ='证据与历史'!G203 -> 131.72025 | I34: ='证据与历史'!H203 -> 156.15728 | J34: ='证据与历史'!G247 -> 197.70626 | K34: ='证据与历史'!H247 -> 240.25352 | L34: ='证据与历史'!G291 -> 255.38791 | M34: ='证据与历史'!H291 -> 213.22059 | N34: 无完整计时 | O34: 无完整计时
A35: 反向 | B35: index_add_ | C35: Tensor.index_add_ / torch.index_add | D35: ='证据与历史'!G116 -> 62.656568 | E35: ='证据与历史'!H116 -> 63.41419 | F35: ='证据与历史'!G160 -> 92.625766 | G35: ='证据与历史'!H160 -> 314.64439 | H35: ='证据与历史'!G204 -> 79.326199 | I35: ='证据与历史'!H204 -> 3341.0332 | J35: 无完整计时 | K35: 无完整计时 | L35: ='证据与历史'!G292 -> 102.65546 | M35: ='证据与历史'!H292 -> 104.79747 | N35: ='证据与历史'!G336 -> 100.98529 | O35: ='证据与历史'!H336 -> 106.96233
A36: 反向 | B36: silu | C36: torch.nn.functional.silu | D36: 无完整计时 | E36: 无完整计时 | F36: ='证据与历史'!G161 -> 135.04908 | G36: ='证据与历史'!H161 -> 307.15971 | H36: ='证据与历史'!G205 -> 131.66594 | I36: ='证据与历史'!H205 -> 204.5226 | J36: ='证据与历史'!G249 -> 140.47965 | K36: ='证据与历史'!H249 -> 251.0841 | L36: ='证据与历史'!G293 -> 146.3641 | M36: ='证据与历史'!H293 -> 253.44254 | N36: 无完整计时 | O36: 无完整计时
A37: 反向 | B37: index | C37: Tensor.__getitem__ | D37: ='证据与历史'!G118 -> 43.046494 | E37: ='证据与历史'!H118 -> 46.927252 | F37: ='证据与历史'!G162 -> 104.64999 | G37: ='证据与历史'!H162 -> 127.95955 | H37: 无完整计时 | I37: 无完整计时 | J37: ='证据与历史'!G250 -> 305.60917 | K37: ='证据与历史'!H250 -> 287.01112 | L37: ='证据与历史'!G294 -> 144.7001 | M37: ='证据与历史'!H294 -> 138.60251 | N37: ='证据与历史'!G338 -> 62.904972 | O37: ='证据与历史'!H338 -> 60.893284
A38: 反向 | B38: add | C38: torch.add | D38: ='证据与历史'!G119 -> 57.814128 | E38: ='证据与历史'!H119 -> 86.324992 | F38: 无完整计时 | G38: 无完整计时 | H38: ='证据与历史'!G207 -> 138.5164 | I38: ='证据与历史'!H207 -> 168.93436 | J38: ='证据与历史'!G251 -> 151.66823 | K38: ='证据与历史'!H251 -> 253.26221 | L38: 无完整计时 | M38: 无完整计时 | N38: ='证据与历史'!G339 -> 78.515049 | O38: ='证据与历史'!H339 -> 107.20592
A39: 反向 | B39: copy_ | C39: torch.ops.aten.copy_ | D39: ='证据与历史'!G120 -> 52.058067 | E39: ='证据与历史'!H120 -> 58.479089 | F39: ='证据与历史'!G164 -> 320.0131 | G39: ='证据与历史'!H164 -> 346.43776 | H39: ='证据与历史'!G208 -> 103.76785 | I39: ='证据与历史'!H208 -> 217.08972 | J39: ='证据与历史'!G252 -> 198.79581 | K39: ='证据与历史'!H252 -> 467.1778 | L39: 无完整计时 | M39: 无完整计时 | N39: ='证据与历史'!G340 -> 78.953987 | O39: ='证据与历史'!H340 -> 73.429988
A40: 反向 | B40: fill_ | C40: torch.ops.aten.fill_ | D40: ='证据与历史'!G121 -> 12.702909 | E40: ='证据与历史'!H121 -> 14.510483 | F40: ='证据与历史'!G165 -> 28.503817 | G40: ='证据与历史'!H165 -> 57.848038 | H40: ='证据与历史'!G209 -> 26.871193 | I40: ='证据与历史'!H209 -> 31.804544 | J40: ='证据与历史'!G253 -> 23.758003 | K40: ='证据与历史'!H253 -> 34.111877 | L40: ='证据与历史'!G297 -> 33.559829 | M40: ='证据与历史'!H297 -> 51.718859 | N40: ='证据与历史'!G341 -> 18.349731 | O40: ='证据与历史'!H341 -> 23.125117
A41: 反向 | B41: mul | C41: torch.mul | D41: 无完整计时 | E41: 无完整计时 | F41: 无完整计时 | G41: 无完整计时 | H41: 无完整计时 | I41: 无完整计时 | J41: 无完整计时 | K41: 无完整计时 | L41: 无完整计时 | M41: 无完整计时 | N41: 无完整计时 | O41: 无完整计时
...

Sheet 证据与历史
A1: 证据与历史｜保留原始数据、诊断、shape和源码；历史与当前计时不混用
A2: 记录类别 | B2: 平台 | C2: 算子/执行名称 | D2: 顶层API/对应运算 | E2: 分类 | F2: 附件H100耗时(ms) | G2: Native耗时(ms) | H2: FlagGems耗时(ms) | I2: Native/FlagGems | J2: Native诊断 | K2: FlagGems诊断 | L2: 覆盖状态 | M2: 运行状态 | N2: 次数 | O2: 代表shape | P2: 阶段 | Q2: 备注 | R2: 未归属耗时(ms) | S2: 原表/来源
A3: 本轮推理 | B3: 华为 910C | C3: addmm（Native参考） | D3: torch.addmm | E3: 稠密计算 | F3: 未复测 | G3: 7750.804 | J3: 整模通过 | K3: 整模通过 | L3: 完整 | M3: 已观测运行 | N3: 17680 / — | O3: [512] [100064,512] [512,512] | P3: 推理 | Q3: Native全量；FG时间在融合/混合组。 对应执行见第19行。 | S3: 华为 910C!A4:O4
A4: 本轮推理 | B4: 华为 910C | C4: cat | D4: torch.cat | E4: 拷贝/布局 | F4: 未复测 | G4: 525.5732 | J4: 整模通过 | K4: 整模通过 | L4: 未计入 | M4: 原包装可运行 | N4: 840 / — | O4: [1, 40962, 512] [1, 40962, 512] dim=-1；模型专项记录 | P4: 推理 | Q4: 未计入FlagGems接管。 | S4: 华为 910C!A5:O5
A5: 本轮推理 | B5: 华为 910C | C5: native_layer_norm | D5: F.layer_norm | E5: 归约/归一化 | F5: 未复测 | G5: 3751.973 | H5: 4003.7489 | I5: =G5/H5 -> 0.93711497 | J5: 整模通过 | K5: 整模通过 | L5: 完整 | M5: 已观测运行 | N5: 4520 / 4520 | O5: [1,100064,512] [512] [512] | P5: 推理 | Q5: 独立计时。 | S5: 华为 910C!A6:O6
A6: 本轮推理 | B6: 华为 910C | C6: index_add_ | D6: Tensor.index_add_ | E6: 索引/聚散 | F6: 未复测 | G6: 6171.5522 | H6: 2018.745 | I6: =G6/H6 -> 3.0571232 | J6: 整模通过 | K6: 整模通过 | L6: 完整 | M6: 已观测运行 | N6: 2120 / 2120 | O6: [1,1038240,512] [100064] [1,100064,512] [1,1038240,512] | P6: 推理 | Q6: 独立计时。 | S6: 华为 910C!A7:O7
A7: 本轮推理 | B7: 华为 910C | C7: silu（独立部分） | D7: F.silu | E7: 激活 | F7: 未复测 | G7: 2521.8362 | H7: 149.42661 | J7: 整模通过 | K7: 整模通过 | L7: 完整 | M7: 已观测运行 | N7: 4560 / 800 | O7: [1,100064,512] | P7: 推理 | Q7: Native为全量；FG仅独立部分。 对应执行见第19行。 | S7: 华为 910C!A8:O8
A8: 本轮推理 | B8: 华为 910C | C8: index | D8: Tensor.__getitem__ | E8: 索引/聚散 | F8: 未复测 | G8: 5769.764 | H8: 4817.0948 | I8: =G8/H8 -> 1.1977684 | J8: 整模通过 | K8: 整模通过 | L8: 完整 | M8: 已观测运行 | N8: 4240 / 4240 | O8: [1038240,1,512] | P8: 推理 | Q8: 独立计时。 | S8: 华为 910C!A9:O9
A9: 本轮推理 | B9: 华为 910C | C9: add（独立部分） | D9: torch.add | E9: 逐元素 | F9: 未复测 | G9: 6197.3184 | H9: 2338.5797 | J9: 整模通过 | K9: 整模通过 | L9: 完整 | M9: 已观测运行 | N9: 6480 / 1840 | O9: [1,100064,512] [1,100064,512] | P9: 推理 | Q9: Native为全量；FG仅独立部分。 对应执行见第17行。 | S9: 华为 910C!A10:O10
A10: 本轮推理 | B10: 华为 910C | C10: all | D10: torch.all | E10: 归约 | F10: 未复测 | G10: 0.089562 | H10: 0.327787 | I10: =G10/H10 -> 0.27323231 | J10: 整模通过 | K10: 整模通过 | L10: 完整 | M10: 已观测运行 | N10: 1 / 2 | O10: [1,1038240,83] | P10: 推理 | Q10: 独立计时。 | S10: 华为 910C!A11:O11
A11: 本轮推理 | B11: 华为 910C | C11: copy_ | D11: Tensor.copy_ | E11: 拷贝/布局 | F11: 未复测 | G11: 1842.2872 | J11: 整模通过 | K11: 整模通过 | L11: 未计入 | M11: Native可运行 | N11: 1961 / — | O11: [1,1038240,13] [1,1038240,13] | P11: 推理 | Q11: 未计入FlagGems接管。 另有未归属 2966.6317 ms，详见证据。 | R11: 2966.6317 | S11: 华为 910C!A12:O12
A12: 本轮推理 | B12: 华为 910C | C12: isfinite | D12: torch.isfinite | E12: 逐元素 | F12: 未复测 | G12: 0.427328 | H12: 2.048581 | I12: =G12/H12 -> 0.20859707 | J12: 整模通过 | K12: 整模通过 | L12: 完整 | M12: 已观测运行 | N12: 1 / 1 | O12: [1,1038240,83] | P12: 推理 | Q12: 独立计时。 | S12: 华为 910C!A13:O13
A13: 本轮推理 | B13: 华为 910C | C13: mul | D13: torch.mul | E13: 逐元素 | F13: 未复测 | G13: 203.6492 | H13: 454.43316 | J13: 整模通过 | K13: 另批次，见证据 | L13: 完整 | M13: 已观测运行 | N13: 800 / 400 | O13: Native：[1,1038240,13] × [13] FG：[1038240,13] × [13] 另含C=1；前后仅无拷贝视图 | P13: 推理 | Q13: 独立计时。 mul为10/21官方新源码，跨批次不求比。 | S13: 华为 910C!A14:O14
A14: 本轮推理 | B14: 华为 910C | C14: zero_ | D14: Tensor.zero_ | E14: 逐元素 | F14: 未复测 | G14: 80.620027 | H14: 153.7169 | I14: =G14/H14 -> 0.5244708 | J14: 整模通过 | K14: 整模通过 | L14: 完整 | M14: 已观测运行 | N14: 1480 / 1516 | O14: [1,1038240,512] | P14: 推理 | Q14: 独立计时。 | S14: 华为 910C!A15:O15
A15: 本轮推理 | B15: 华为 910C | C15: add_add_silu | D15: add × 2 → silu | E15: 融合 | F15: 未复测 | H15: 2807.7276 | L15: 不单独计覆盖率 | M15: 已观测运行 | N15: — / 2120 | O15: 未逐kernel拆shape，见证据 | P15: 推理 | Q15: 融合时间只记本行。 | S15: 华为 910C!A17:O17
A16: 本轮推理 | B16: 华为 910C | C16: addmm / addmm_silu（未拆分） | D16: addmm；部分调用融合 silu | E16: 含融合内核组 | F16: 未复测 | H16: 13758.866 | L16: 不单独计覆盖率 | M16: 已观测运行 | N16: — / 10560 | O16: 未逐kernel拆shape，见证据 | P16: 推理 | Q16: 普通/融合调用未拆，不能当纯融合耗时。 | S16: 华为 910C!A19:O19
A17: 本轮推理 | B17: 华为 910C | C17: aminmax（未归属） | D17: aminmax | E17: 未确认归属 | F17: 未复测 | L17: 不单独计覆盖率 | M17: 未证实FlagGems | N17: 未归属：4240 | O17: 未逐kernel拆shape，见证据 | P17: 推理 | Q17: 不是已确认FlagGems，不填FG耗时。 另有未归属 207.6601 ms，详见证据。 | R17: 207.66011 | S17: 华为 910C!A21:O21
A18: 本轮推理 | B18: 平头哥 810E | C18: addmm | D18: torch.addmm | E18: 稠密计算 | F18: 未复测 | G18: 13818.696 | H18: 46547.617 | I18: =G18/H18 -> 0.29687226 | J18: 整模通过 | K18: 整模通过 | L18: 完整 | M18: 已观测运行 | N18: 10560 / 10560 | O18: [[512], [100064, 512], [512, 512], [], []] | P18: 推理 | Q18: 独立计时。 | S18: 平头哥 810E!A4:O4
A19: 本轮推理 | B19: 平头哥 810E | C19: cat | D19: torch.cat | E19: 拷贝/布局 | F19: 未复测 | G19: 361.35177 | H19: 398.20417 | I19: =G19/H19 -> 0.90745351 | J19: 整模通过 | K19: 整模通过 | L19: 完整 | M19: 已观测运行 | N19: 840 / 840 | O19: [[[1, 1038240, 176], [1, 1038240, 5]], []] | P19: 推理 | Q19: 独立计时。 | S19: 平头哥 810E!A5:O5
A20: 本轮推理 | B20: 平头哥 810E | C20: native_layer_norm | D20: F.layer_norm | E20: 归约/归一化 | F20: 未复测 | G20: 2180.4498 | H20: 1492.2736 | I20: =G20/H20 -> 1.4611595 | J20: 整模通过 | K20: 整模通过 | L20: 完整 | M20: 已观测运行 | N20: 4520 / 4520 | O20: [[1, 100064, 512], [], [512], [512], []] | P20: 推理 | Q20: 独立计时。 | S20: 平头哥 810E!A6:O6
A21: 本轮推理 | B21: 平头哥 810E | C21: index_add_ | D21: Tensor.index_add_ | E21: 索引/聚散 | F21: 未复测 | G21: 2392.6995 | H21: 2222.5714 | I21: =G21/H21 -> 1.0765456 | J21: 整模通过 | K21: 整模通过 | L21: 完整 | M21: 已观测运行 | N21: 2120 / 2120 | O21: [[1, 1038240, 512], [], [100064], [1, 100064, 512], []] | P21: 推理 | Q21: 独立计时。 | S21: 平头哥 810E!A7:O7
A22: 本轮推理 | B22: 平头哥 810E | C22: silu | D22: F.silu | E22: 激活 | F22: 未复测 | G22: 1607.476 | H22: 1584.42 | I22: =G22/H22 -> 1.0145517 | J22: 整模通过 | K22: 整模通过 | L22: 完整 | M22: 已观测运行 | N22: 4560 / 4560 | O22: [[1, 100064, 512]] | P22: 推理 | Q22: 独立计时。 | S22: 平头哥 810E!A8:O8
A23: 本轮推理 | B23: 平头哥 810E | C23: index | D23: Tensor.__getitem__ | E23: 索引/聚散 | F23: 未复测 | G23: 1156.2951 | H23: 992.92191 | I23: =G23/H23 -> 1.1645379 | J23: 整模通过 | K23: 整模通过 | L23: 完整 | M23: 已观测运行 | N23: 4240 / 4240 | O23: [[1038240, 1, 512], []] | P23: 推理 | Q23: 独立计时。 | S23: 平头哥 810E!A9:O9
A24: 本轮推理 | B24: 平头哥 810E | C24: add | D24: torch.add | E24: 逐元素 | F24: 未复测 | G24: 3357.636 | H24: 3350.9121 | I24: =G24/H24 -> 1.0020066 | J24: 整模通过 | K24: 整模通过 | L24: 完整 | M24: 已观测运行 | N24: 6080 / 6080 | O24: [[1, 100064, 512], [1, 100064, 512], []] | P24: 推理 | Q24: 独立计时。 | S24: 平头哥 810E!A10:O10
A25: 本轮推理 | B25: 平头哥 810E | C25: abs | D25: torch.abs | E25: 逐元素 | F25: 未复测 | G25: 0.344723 | H25: 0.346883 | I25: =G25/H25 -> 0.99377312 | J25: 整模通过 | K25: 整模通过 | L25: 完整 | M25: 已观测运行 | N25: 1 / 1 | O25: [[1, 1038240, 83], [0]] | P25: 推理 | Q25: 独立计时。 | S25: 平头哥 810E!A11:O11
A26: 本轮推理 | B26: 平头哥 810E | C26: all | D26: torch.all | E26: 归约 | F26: 未复测 | G26: 0.093401 | H26: 7.618454 | I26: =G26/H26 -> 0.012259836 | J26: 整模通过 | K26: 整模通过 | L26: 完整 | M26: 已观测运行 | N26: 1 / 4242 | O26: [[1, 1038240, 83]] | P26: 推理 | Q26: 独立计时。 | S26: 平头哥 810E!A12:O12
A27: 本轮推理 | B27: 平头哥 810E | C27: copy_（部分接管） | D27: Tensor.copy_ | E27: 拷贝/布局 | F27: 未复测 | G27: 221.63738 | H27: 121.93949 | J27: 整模通过 | K27: 整模通过 | L27: 部分 | M27: 已观测运行 | N27: 1180 / 596 | O27: [[1, 1038240, 13], [1, 1038240, 13], []] | P27: 推理 | Q27: Native为全量；FG仅已确认部分。 另有未归属 99.8709 ms，详见证据。 | R27: 99.870931 | S27: 平头哥 810E!A13:O13
A28: 本轮推理 | B28: 平头哥 810E | C28: eq | D28: torch.eq | E28: 逐元素 | F28: 未复测 | G28: 0.202642 | H28: 0.195922 | I28: =G28/H28 -> 1.0342994 | J28: 整模通过 | K28: 整模通过 | L28: 完整 | M28: 已观测运行 | N28: 1 / 1 | O28: [[1, 1038240, 83], [1, 1038240, 83]] | P28: 推理 | Q28: 独立计时。 | S28: 平头哥 810E!A14:O14
A29: 本轮推理 | B29: 平头哥 810E | C29: fill_ | D29: Tensor.fill_ | E29: 逐元素 | F29: 未复测 | G29: 66.321168 | H29: 2.673025 | I29: =G29/H29 -> 24.811279 | J29: 整模通过 | K29: 整模通过 | L29: 完整 | M29: 已观测运行 | N29: 1480 / 2132 | O29: [[1, 1038240, 512], []] | P29: 推理 | Q29: 独立计时。 | S29: 平头哥 810E!A15:O15
A30: 本轮推理 | B30: 平头哥 810E | C30: mul | D30: torch.mul | E30: 逐元素 | F30: 未复测 | G30: 50.95436 | H30: 69.706643 | I30: =G30/H30 -> 0.73098284 | J30: 整模通过 | K30: 整模通过 | L30: 完整 | M30: 已观测运行 | N30: 401 / 2677 | O30: [[1, 1038240, 13], [13]] | P30: 推理 | Q30: 独立计时。 | S30: 平头哥 810E!A16:O16
A31: 本轮推理 | B31: 平头哥 810E | C31: ne | D31: torch.ne | E31: 逐元素 | F31: 未复测 | G31: 0.213921 | H31: 0.208361 | I31: =G31/H31 -> 1.0266845 | J31: 整模通过 | K31: 整模通过 | L31: 完整 | M31: 已观测运行 | N31: 1 / 1 | O31: [[1, 1038240, 83], []] | P31: 推理 | Q31: 独立计时。 | S31: 平头哥 810E!A17:O17
A32: 本轮推理 | B32: 平头哥 810E | C32: zero_ | D32: zero_ | E32: 辅助执行 | F32: 未复测 | H32: 64.77564 | L32: 不单独计覆盖率 | M32: 已观测运行 | N32: — / 1480 | O32: 未逐kernel拆shape，见证据 | P32: 推理 | Q32: 独立执行计时，不新增覆盖率类型。 | S32: 平头哥 810E!A19:O19
A33: 本轮推理 | B33: 平头哥 810E | C33: equal（未归属） | D33: equal | E33: 未确认归属 | F33: 未复测 | L33: 不单独计覆盖率 | M33: 未证实FlagGems | N33: 未归属：2120 | O33: 未逐kernel拆shape，见证据 | P33: 推理 | Q33: 不是已确认FlagGems，不填FG耗时。 另有未归属 5.6493 ms，详见证据。 | R33: 5.649332 | S33: 平头哥 810E!A21:O21
A34: 本轮推理 | B34: 平头哥 810E | C34: ge（未归属） | D34: ge | E34: 未确认归属 | F34: 未复测 | L34: 不单独计覆盖率 | M34: 未证实FlagGems | N34: 未归属：2120 | O34: 未逐kernel拆shape，见证据 | P34: 推理 | Q34: 不是已确认FlagGems，不填FG耗时。 另有未归属 7.5814 ms，详见证据。 | R34: 7.581379 | S34: 平头哥 810E!A22:O22
A35: 本轮推理 | B35: 平头哥 810E | C35: lt（未归属） | D35: lt | E35: 未确认归属 | F35: 未复测 | L35: 不单独计覆盖率 | M35: 未证实FlagGems | N35: 未归属：2120 | O35: 未逐kernel拆shape，见证据 | P35: 推理 | Q35: 不是已确认FlagGems，不填FG耗时。 另有未归属 4.6980 ms，详见证据。 | R35: 4.697951 | S35: 平头哥 810E!A23:O23
A36: 本轮推理 | B36: 摩尔线程 S5000 | C36: addmm（矩阵计算） | D36: torch.addmm | E36: 稠密计算 | F36: 未复测 | G36: 6063.2013 | H36: 8475.0823 | J36: 整模未通过 | K36: 整模通过 | L36: 完整 | M36: 已观测运行 | N36: 10560 / 10560 | O36: [[512], [100064, 4], [4, 512], [], []] | P36: 推理 | Q36: FG仅矩阵内核，输入打包另行。 Native整模诊断未过，不填加速比。 对应执行见第24行。 | S36: 摩尔线程 S5000!A4:O4
A37: 本轮推理 | B37: 摩尔线程 S5000 | C37: cat | D37: torch.cat | E37: 拷贝/布局 | F37: 未复测 | G37: 511.91909 | H37: 4642.5603 | J37: 整模未通过 | K37: 整模通过 | L37: 完整 | M37: 已观测运行 | N37: 840 / 840 | O37: [[[1, 1038240, 512], [1, 1038240, 512]], []] | P37: 推理 | Q37: 独立计时。 Native整模诊断未过，不填加速比。 | S37: 摩尔线程 S5000!A5:O5
A38: 本轮推理 | B38: 摩尔线程 S5000 | C38: native_layer_norm（独立部分） | D38: F.layer_norm | E38: 归约/归一化 | F38: 未复测 | G38: 2557.9691 | H38: 2054.5788 | J38: 整模未通过 | K38: 整模通过 | L38: 完整 | M38: 已观测运行 | N38: 4520 / 3720 | O38: [[1, 100064, 512], [], [512], [512], []] | P38: 推理 | Q38: Native为全量；FG仅独立部分。 Native整模诊断未过，不填加速比。 对应执行见第22行。 | S38: 摩尔线程 S5000!A6:O6
A39: 本轮推理 | B39: 摩尔线程 S5000 | C39: index_add_ | D39: Tensor.index_add_ | E39: 索引/聚散 | F39: 未复测 | G39: 1880.8756 | H39: 1650.2695 | J39: 整模未通过 | K39: 整模通过 | L39: 完整 | M39: 已观测运行 | N39: 2120 / 2120 | O39: [[1, 1038240, 512], [], [100064], [1, 100064, 512], []] | P39: 推理 | Q39: 独立计时。 Native整模诊断未过，不填加速比。 | S39: 摩尔线程 S5000!A7:O7
A40: 本轮推理 | B40: 摩尔线程 S5000 | C40: silu（独立部分） | D40: F.silu | E40: 激活 | F40: 未复测 | G40: 2468.7596 | H40: 125.92526 | J40: 整模未通过 | K40: 整模通过 | L40: 完整 | M40: 已观测运行 | N40: 4560 / 40 | O40: [[1, 100064, 512]] | P40: 推理 | Q40: Native为全量；FG仅独立部分。 Native整模诊断未过，不填加速比。 对应执行见第20行。 | S40: 摩尔线程 S5000!A8:O8
...
